2024-09-24 22:27:39 [INFO] Question: Diu lei lou mou
2024-09-24 22:27:40 [INFO] Running PandasAI with langchain_ollama-llm LLM...
2024-09-24 22:27:40 [INFO] Prompt ID: 47243668-62df-4ebb-b25f-dfb34bc24bf0
2024-09-24 22:27:40 [INFO] Executing Pipeline: GenerateChatPipeline
2024-09-24 22:27:40 [INFO] Executing Step 0: ValidatePipelineInput
2024-09-24 22:27:40 [INFO] Executing Step 1: CacheLookup
2024-09-24 22:27:40 [INFO] Executing Step 2: PromptGeneration
2024-09-24 22:27:40 [INFO] Using prompt: <dataframe>
dfs[0]:2000x11
LineId,Month,Date,Time,User,Component,PID,Address,Content,EventId,EventTemplate
1700,Jul,1,04:40:17,calvisitor-10-105-161-225,secd,34235,,"hostControllerOnline - Number of Paired devices = 1, List of Paired devices = ( ""84-41-67-32-db-e1"" )",E175,<*>:<*>:<*>.<*> : Discoverable mode changed to Off
1494,Jul,8,20:51:27,calvisitor-10-105-163-253,WindowServer,31174,[31376],"com.apple.Safari.SafeBrowsing.Update: scheduler_evaluate_activity told me to run this job; however, but the start time isn't for 2165 seconds.  Ignoring.",E16,tcp_connection_tls_session_error_callback_imp <*> tcp_connection_tls_session_handle_read_error.<*> error <*>
1869,Jul,3,14:01:24,airbears2-10-142-108-38,com.apple.WebKit.Networking,33452,com.apple.xpc.launchd.domain.pid.WebContent.35830,"com.apple.SoftwareUpdate.Activity: scheduler_evaluate_activity told me to run this job; however, but the start time isn't for 5703 seconds.  Ignoring.",E289,en0: channel changed to <*>
</dataframe>




Update this initial code:
```python
# TODO: import the required dependencies
import pandas as pd

# Write code here

# Declare result var: 
type (possible values "string", "number", "dataframe", "plot"). Examples: { "type": "string", "value": f"The highest salary is {highest_salary}." } or { "type": "number", "value": 125 } or { "type": "dataframe", "value": pd.DataFrame({...}) } or { "type": "plot", "value": "temp_chart.png" }

```



### QUERY
 Diu lei lou mou

Variable `dfs: list[pd.DataFrame]` is already declared.

At the end, declare "result" variable as a dictionary of type and value.

If you are asked to plot a chart, use "matplotlib" for charts, save as png.


Generate python code and return full updated code:
2024-09-24 22:27:40 [INFO] Executing Step 3: CodeGenerator
2024-09-24 22:27:56 [INFO] Prompt used:
            
<dataframe>
dfs[0]:2000x11
LineId,Month,Date,Time,User,Component,PID,Address,Content,EventId,EventTemplate
1700,Jul,1,04:40:17,calvisitor-10-105-161-225,secd,34235,,"hostControllerOnline - Number of Paired devices = 1, List of Paired devices = ( ""84-41-67-32-db-e1"" )",E175,<*>:<*>:<*>.<*> : Discoverable mode changed to Off
1494,Jul,8,20:51:27,calvisitor-10-105-163-253,WindowServer,31174,[31376],"com.apple.Safari.SafeBrowsing.Update: scheduler_evaluate_activity told me to run this job; however, but the start time isn't for 2165 seconds.  Ignoring.",E16,tcp_connection_tls_session_error_callback_imp <*> tcp_connection_tls_session_handle_read_error.<*> error <*>
1869,Jul,3,14:01:24,airbears2-10-142-108-38,com.apple.WebKit.Networking,33452,com.apple.xpc.launchd.domain.pid.WebContent.35830,"com.apple.SoftwareUpdate.Activity: scheduler_evaluate_activity told me to run this job; however, but the start time isn't for 5703 seconds.  Ignoring.",E289,en0: channel changed to <*>
</dataframe>




Update this initial code:
```python
# TODO: import the required dependencies
import pandas as pd

# Write code here

# Declare result var: 
type (possible values "string", "number", "dataframe", "plot"). Examples: { "type": "string", "value": f"The highest salary is {highest_salary}." } or { "type": "number", "value": 125 } or { "type": "dataframe", "value": pd.DataFrame({...}) } or { "type": "plot", "value": "temp_chart.png" }

```



### QUERY
 Diu lei lou mou

Variable `dfs: list[pd.DataFrame]` is already declared.

At the end, declare "result" variable as a dictionary of type and value.

If you are asked to plot a chart, use "matplotlib" for charts, save as png.


Generate python code and return full updated code:
            
2024-09-24 22:27:56 [INFO] Code generated:
            ```
            # TODO: import the required dependencies
import pandas as pd
import matplotlib.pyplot as plt

# Declare dfs variable:
dfs = [pd.DataFrame({
    'LineId': [1700, 1494, 1869],
    'Month': ['Jul', 'Jul', 'Jul'],
    'Date': ['1', '8', '3'],
    'Time': ['04:40:17', '20:51:27', '14:01:24'],
    'User': ['calvisitor-10-105-161-225', 'calvisitor-10-105-163-253', 'airbears2-10-142-108-38'],
    'Component': ['secd', 'WindowServer', 'com.apple.WebKit.Networking'],
    'PID': [34235, 31174, 33452],
    'Address': ['', '[31376]', ''],
    'Content': ["hostControllerOnline - Number of Paired devices = 1, List of Paired devices = ( \"84-41-67-32-db-e1\" )", "com.apple.Safari.SafeBrowsing.Update: scheduler_evaluate_activity told me to run this job; however, but the start time isn't for 2165 seconds.  Ignoring.", "com.apple.SoftwareUpdate.Activity: scheduler_evaluate_activity told me to run this job; however, but the start time isn't for 5703 seconds.  Ignoring."],
    'EventId': ['E175', 'E16', 'E289'],
    'EventTemplate': ['', '', '']
})]

# Write code here
# Let's say we want to find the user with the most events
max_events_user = dfs[0]['User'][dfs[0]['LineId'].idxmax()]
result = {"type": "string", "value": f"The user with the most events is {max_events_user}."}

# If you are asked to plot a chart, use "matplotlib" for charts, save as png
# Let's say we want to plot a bar chart of the number of events per month
events_per_month = dfs[0].groupby('Month')['LineId'].count().reset_index()
plt.bar(events_per_month['Month'], events_per_month['LineId'])
plt.title('Number of Events per Month')
plt.xlabel('Month')
plt.ylabel('Number of Events')
plt.savefig('temp_chart.png')

result = {"type": "plot", "value": 'temp_chart.png'}
            ```
            
2024-09-24 22:27:56 [INFO] Executing Step 4: CachePopulation
2024-09-24 22:27:56 [INFO] Executing Step 5: CodeCleaning
2024-09-24 22:27:56 [INFO] Saving charts to C:\Users\regan\Documents\NUS\NUS Modules\Year 4 Semester 1\BT4103\log-alchemist\agent_v0\exports\charts\temp_chart.png
2024-09-24 22:27:56 [INFO] 
Code running:
```
max_events_user = dfs[0]['User'][dfs[0]['LineId'].idxmax()]
result = {'type': 'string', 'value': f'The user with the most events is {max_events_user}.'}
events_per_month = dfs[0].groupby('Month')['LineId'].count().reset_index()
plt.bar(events_per_month['Month'], events_per_month['LineId'])
plt.title('Number of Events per Month')
plt.xlabel('Month')
plt.ylabel('Number of Events')
plt.savefig('C:/Users/regan/Documents/NUS/NUS Modules/Year 4 Semester 1/BT4103/log-alchemist/agent_v0/exports/charts/temp_chart.png')
result = {'type': 'plot', 'value': 'C:/Users/regan/Documents/NUS/NUS Modules/Year 4 Semester 1/BT4103/log-alchemist/agent_v0/exports/charts/temp_chart.png'}
        ```
2024-09-24 22:27:56 [INFO] Executing Step 6: CodeExecution
2024-09-24 22:27:57 [INFO] Using categorical units to plot a list of strings that are all parsable as floats or dates. If these strings should be plotted as numbers, cast to the appropriate data type before plotting.
2024-09-24 22:27:57 [INFO] Using categorical units to plot a list of strings that are all parsable as floats or dates. If these strings should be plotted as numbers, cast to the appropriate data type before plotting.
2024-09-24 22:27:57 [ERROR] Failed with error: Traceback (most recent call last):
  File "C:\Users\regan\Documents\NUS\NUS Modules\Year 4 Semester 1\BT4103\.venv\lib\site-packages\pandasai\pipelines\chat\code_execution.py", line 97, in execute
    raise InvalidOutputValueMismatch(
pandasai.exceptions.InvalidOutputValueMismatch: Value type <class 'str'> must match with type plot

2024-09-24 22:27:57 [WARNING] Failed to execute code retrying with a correction framework [retry number: 1]
2024-09-24 22:27:57 [INFO] Executing Pipeline: ErrorCorrectionPipeline
2024-09-24 22:27:57 [INFO] Executing Step 0: ErrorPromptGeneration
2024-09-24 22:27:57 [INFO] Using prompt: <dataframe>
dfs[0]:2000x11
LineId,Month,Date,Time,User,Component,PID,Address,Content,EventId,EventTemplate
1700,Jul,1,04:40:17,calvisitor-10-105-161-225,secd,34235,,"hostControllerOnline - Number of Paired devices = 1, List of Paired devices = ( ""84-41-67-32-db-e1"" )",E175,<*>:<*>:<*>.<*> : Discoverable mode changed to Off
1494,Jul,8,20:51:27,calvisitor-10-105-163-253,WindowServer,31174,[31376],"com.apple.Safari.SafeBrowsing.Update: scheduler_evaluate_activity told me to run this job; however, but the start time isn't for 2165 seconds.  Ignoring.",E16,tcp_connection_tls_session_error_callback_imp <*> tcp_connection_tls_session_handle_read_error.<*> error <*>
1869,Jul,3,14:01:24,airbears2-10-142-108-38,com.apple.WebKit.Networking,33452,com.apple.xpc.launchd.domain.pid.WebContent.35830,"com.apple.SoftwareUpdate.Activity: scheduler_evaluate_activity told me to run this job; however, but the start time isn't for 5703 seconds.  Ignoring.",E289,en0: channel changed to <*>
</dataframe>


The user asked the following question:
### QUERY
 Diu lei lou mou

You generated this python code:
max_events_user = dfs[0]['User'][dfs[0]['LineId'].idxmax()]
result = {'type': 'string', 'value': f'The user with the most events is {max_events_user}.'}
events_per_month = dfs[0].groupby('Month')['LineId'].count().reset_index()
plt.bar(events_per_month['Month'], events_per_month['LineId'])
plt.title('Number of Events per Month')
plt.xlabel('Month')
plt.ylabel('Number of Events')
plt.savefig('C:/Users/regan/Documents/NUS/NUS Modules/Year 4 Semester 1/BT4103/log-alchemist/agent_v0/exports/charts/temp_chart.png')
result = {'type': 'plot', 'value': 'C:/Users/regan/Documents/NUS/NUS Modules/Year 4 Semester 1/BT4103/log-alchemist/agent_v0/exports/charts/temp_chart.png'}

It fails with the following error:
Traceback (most recent call last):
  File "C:\Users\regan\Documents\NUS\NUS Modules\Year 4 Semester 1\BT4103\.venv\lib\site-packages\pandasai\pipelines\chat\code_execution.py", line 97, in execute
    raise InvalidOutputValueMismatch(
pandasai.exceptions.InvalidOutputValueMismatch: Value type <class 'str'> must match with type plot


Fix the python code above and return the new python code:
2024-09-24 22:27:57 [INFO] Executing Step 1: CodeGenerator
2024-09-24 22:28:05 [INFO] Prompt used:
            
<dataframe>
dfs[0]:2000x11
LineId,Month,Date,Time,User,Component,PID,Address,Content,EventId,EventTemplate
1700,Jul,1,04:40:17,calvisitor-10-105-161-225,secd,34235,,"hostControllerOnline - Number of Paired devices = 1, List of Paired devices = ( ""84-41-67-32-db-e1"" )",E175,<*>:<*>:<*>.<*> : Discoverable mode changed to Off
1494,Jul,8,20:51:27,calvisitor-10-105-163-253,WindowServer,31174,[31376],"com.apple.Safari.SafeBrowsing.Update: scheduler_evaluate_activity told me to run this job; however, but the start time isn't for 2165 seconds.  Ignoring.",E16,tcp_connection_tls_session_error_callback_imp <*> tcp_connection_tls_session_handle_read_error.<*> error <*>
1869,Jul,3,14:01:24,airbears2-10-142-108-38,com.apple.WebKit.Networking,33452,com.apple.xpc.launchd.domain.pid.WebContent.35830,"com.apple.SoftwareUpdate.Activity: scheduler_evaluate_activity told me to run this job; however, but the start time isn't for 5703 seconds.  Ignoring.",E289,en0: channel changed to <*>
</dataframe>


The user asked the following question:
### QUERY
 Diu lei lou mou

You generated this python code:
max_events_user = dfs[0]['User'][dfs[0]['LineId'].idxmax()]
result = {'type': 'string', 'value': f'The user with the most events is {max_events_user}.'}
events_per_month = dfs[0].groupby('Month')['LineId'].count().reset_index()
plt.bar(events_per_month['Month'], events_per_month['LineId'])
plt.title('Number of Events per Month')
plt.xlabel('Month')
plt.ylabel('Number of Events')
plt.savefig('C:/Users/regan/Documents/NUS/NUS Modules/Year 4 Semester 1/BT4103/log-alchemist/agent_v0/exports/charts/temp_chart.png')
result = {'type': 'plot', 'value': 'C:/Users/regan/Documents/NUS/NUS Modules/Year 4 Semester 1/BT4103/log-alchemist/agent_v0/exports/charts/temp_chart.png'}

It fails with the following error:
Traceback (most recent call last):
  File "C:\Users\regan\Documents\NUS\NUS Modules\Year 4 Semester 1\BT4103\.venv\lib\site-packages\pandasai\pipelines\chat\code_execution.py", line 97, in execute
    raise InvalidOutputValueMismatch(
pandasai.exceptions.InvalidOutputValueMismatch: Value type <class 'str'> must match with type plot


Fix the python code above and return the new python code:
            
2024-09-24 22:28:05 [INFO] Code generated:
            ```
            max_events_user = dfs[0]['User'][dfs[0]['LineId'].idxmax()]
result = {'type': 'string', 'value': f'The user with the most events is {max_events_user}.'}
events_per_month = dfs[0].groupby('Month')['LineId'].count().reset_index()
plt.bar(events_per_month['Month'], events_per_month['LineId'])
plt.title('Number of Events per Month')
plt.xlabel('Month')
plt.ylabel('Number of Events')
result = {'type': 'plot', 'value': 'C:/Users/regan/Documents/NUS/NUS Modules/Year 4 Semester 1/BT4103/log-alchemist/agent_v0/exports/charts/temp_chart.png'}
plt.savefig(result['value'])
            ```
            
2024-09-24 22:28:05 [INFO] Executing Step 2: CodeCleaning
2024-09-24 22:28:05 [INFO] Saving charts to C:\Users\regan\Documents\NUS\NUS Modules\Year 4 Semester 1\BT4103\log-alchemist\agent_v0\exports\charts\temp_chart.png
2024-09-24 22:28:05 [INFO] 
Code running:
```
max_events_user = dfs[0]['User'][dfs[0]['LineId'].idxmax()]
result = {'type': 'string', 'value': f'The user with the most events is {max_events_user}.'}
events_per_month = dfs[0].groupby('Month')['LineId'].count().reset_index()
plt.bar(events_per_month['Month'], events_per_month['LineId'])
plt.title('Number of Events per Month')
plt.xlabel('Month')
plt.ylabel('Number of Events')
result = {'type': 'plot', 'value': 'C:/Users/regan/Documents/NUS/NUS Modules/Year 4 Semester 1/BT4103/log-alchemist/agent_v0/exports/charts/temp_chart.png'}
plt.savefig(result['value'])
        ```
2024-09-24 22:28:05 [INFO] Using categorical units to plot a list of strings that are all parsable as floats or dates. If these strings should be plotted as numbers, cast to the appropriate data type before plotting.
2024-09-24 22:28:05 [ERROR] Failed with error: Traceback (most recent call last):
  File "C:\Users\regan\Documents\NUS\NUS Modules\Year 4 Semester 1\BT4103\.venv\lib\site-packages\pandasai\pipelines\chat\code_execution.py", line 97, in execute
    raise InvalidOutputValueMismatch(
pandasai.exceptions.InvalidOutputValueMismatch: Value type <class 'str'> must match with type plot

2024-09-24 22:28:05 [WARNING] Failed to execute code retrying with a correction framework [retry number: 2]
2024-09-24 22:28:05 [INFO] Executing Pipeline: ErrorCorrectionPipeline
2024-09-24 22:28:05 [INFO] Executing Step 0: ErrorPromptGeneration
2024-09-24 22:28:05 [INFO] Using prompt: <dataframe>
dfs[0]:2000x11
LineId,Month,Date,Time,User,Component,PID,Address,Content,EventId,EventTemplate
1700,Jul,1,04:40:17,calvisitor-10-105-161-225,secd,34235,,"hostControllerOnline - Number of Paired devices = 1, List of Paired devices = ( ""84-41-67-32-db-e1"" )",E175,<*>:<*>:<*>.<*> : Discoverable mode changed to Off
1494,Jul,8,20:51:27,calvisitor-10-105-163-253,WindowServer,31174,[31376],"com.apple.Safari.SafeBrowsing.Update: scheduler_evaluate_activity told me to run this job; however, but the start time isn't for 2165 seconds.  Ignoring.",E16,tcp_connection_tls_session_error_callback_imp <*> tcp_connection_tls_session_handle_read_error.<*> error <*>
1869,Jul,3,14:01:24,airbears2-10-142-108-38,com.apple.WebKit.Networking,33452,com.apple.xpc.launchd.domain.pid.WebContent.35830,"com.apple.SoftwareUpdate.Activity: scheduler_evaluate_activity told me to run this job; however, but the start time isn't for 5703 seconds.  Ignoring.",E289,en0: channel changed to <*>
</dataframe>


The user asked the following question:
### QUERY
 Diu lei lou mou

You generated this python code:
max_events_user = dfs[0]['User'][dfs[0]['LineId'].idxmax()]
result = {'type': 'string', 'value': f'The user with the most events is {max_events_user}.'}
events_per_month = dfs[0].groupby('Month')['LineId'].count().reset_index()
plt.bar(events_per_month['Month'], events_per_month['LineId'])
plt.title('Number of Events per Month')
plt.xlabel('Month')
plt.ylabel('Number of Events')
result = {'type': 'plot', 'value': 'C:/Users/regan/Documents/NUS/NUS Modules/Year 4 Semester 1/BT4103/log-alchemist/agent_v0/exports/charts/temp_chart.png'}
plt.savefig(result['value'])

It fails with the following error:
Traceback (most recent call last):
  File "C:\Users\regan\Documents\NUS\NUS Modules\Year 4 Semester 1\BT4103\.venv\lib\site-packages\pandasai\pipelines\chat\code_execution.py", line 97, in execute
    raise InvalidOutputValueMismatch(
pandasai.exceptions.InvalidOutputValueMismatch: Value type <class 'str'> must match with type plot


Fix the python code above and return the new python code:
2024-09-24 22:28:05 [INFO] Executing Step 1: CodeGenerator
2024-09-24 22:29:37 [INFO] Question: How many rows are in the data?
2024-09-24 22:29:38 [INFO] Running PandasAI with langchain_ollama-llm LLM...
2024-09-24 22:29:38 [INFO] Prompt ID: cf9ad7fe-7e77-4da6-816b-1bca473fe2eb
2024-09-24 22:29:38 [INFO] Executing Pipeline: GenerateChatPipeline
2024-09-24 22:29:38 [INFO] Executing Step 0: ValidatePipelineInput
2024-09-24 22:29:38 [INFO] Executing Step 1: CacheLookup
2024-09-24 22:29:38 [INFO] Executing Step 2: PromptGeneration
2024-09-24 22:29:38 [INFO] Using prompt: <dataframe>
dfs[0]:2000x11
LineId,Month,Date,Time,User,Component,PID,Address,Content,EventId,EventTemplate
1099,Jul,1,09:01:48,calvisitor-10-105-162-124,AddressBookSourceSync,31198,com.apple.xpc.launchd.domain.pid.WebContent.37146,"com.apple.CacheDelete.daily: scheduler_evaluate_activity told me to run this job; however, but the start time isn't for 26656 seconds.  Ignoring.",E100,INIT -- Host controller is published
971,Jul,5,19:50:12,calvisitor-10-105-163-202,com.apple.ncplugin.WorldClock,91,,"CCDataTap::profileRemoved, Owner: com.apple.driver.AirPort.Brcm4360.0, Name: StateSnapshots",E258,hibernate_rebuild_pmap_structs done: last_valid_compact_indx <*>
525,Jul,6,05:16:28,calvisitor-10-105-160-95,secd,35382,com.apple.xpc.launchd.domain.pid.WebContent.39146,Cocoa scripting error for '0x029f003a': four character codes must be four characters long.,E144,Invalidating watch set.
</dataframe>




Update this initial code:
```python
# TODO: import the required dependencies
import pandas as pd

# Write code here

# Declare result var: 
type (possible values "string", "number", "dataframe", "plot"). Examples: { "type": "string", "value": f"The highest salary is {highest_salary}." } or { "type": "number", "value": 125 } or { "type": "dataframe", "value": pd.DataFrame({...}) } or { "type": "plot", "value": "temp_chart.png" }

```



### QUERY
 How many rows are in the data?

Variable `dfs: list[pd.DataFrame]` is already declared.

At the end, declare "result" variable as a dictionary of type and value.

If you are asked to plot a chart, use "matplotlib" for charts, save as png.


Generate python code and return full updated code:
2024-09-24 22:29:38 [INFO] Executing Step 3: CodeGenerator
2024-09-24 22:29:50 [INFO] Prompt used:
            
<dataframe>
dfs[0]:2000x11
LineId,Month,Date,Time,User,Component,PID,Address,Content,EventId,EventTemplate
1099,Jul,1,09:01:48,calvisitor-10-105-162-124,AddressBookSourceSync,31198,com.apple.xpc.launchd.domain.pid.WebContent.37146,"com.apple.CacheDelete.daily: scheduler_evaluate_activity told me to run this job; however, but the start time isn't for 26656 seconds.  Ignoring.",E100,INIT -- Host controller is published
971,Jul,5,19:50:12,calvisitor-10-105-163-202,com.apple.ncplugin.WorldClock,91,,"CCDataTap::profileRemoved, Owner: com.apple.driver.AirPort.Brcm4360.0, Name: StateSnapshots",E258,hibernate_rebuild_pmap_structs done: last_valid_compact_indx <*>
525,Jul,6,05:16:28,calvisitor-10-105-160-95,secd,35382,com.apple.xpc.launchd.domain.pid.WebContent.39146,Cocoa scripting error for '0x029f003a': four character codes must be four characters long.,E144,Invalidating watch set.
</dataframe>




Update this initial code:
```python
# TODO: import the required dependencies
import pandas as pd

# Write code here

# Declare result var: 
type (possible values "string", "number", "dataframe", "plot"). Examples: { "type": "string", "value": f"The highest salary is {highest_salary}." } or { "type": "number", "value": 125 } or { "type": "dataframe", "value": pd.DataFrame({...}) } or { "type": "plot", "value": "temp_chart.png" }

```



### QUERY
 How many rows are in the data?

Variable `dfs: list[pd.DataFrame]` is already declared.

At the end, declare "result" variable as a dictionary of type and value.

If you are asked to plot a chart, use "matplotlib" for charts, save as png.


Generate python code and return full updated code:
            
2024-09-24 22:29:50 [INFO] Code generated:
            ```
            # Import required dependencies
import pandas as pd

# Declare result var:
result = {}

# Update this initial code
dfs = [pd.DataFrame({
    "LineId": [1099, 971, 525],
    "Month": ["Jul", "Jul", "Jul"],
    "Date": ["1", "5", "6"],
    "Time": ["09:01:48", "19:50:12", "05:16:28"],
    "User": ["calvisitor-10-105-162-124", "calvisitor-10-105-163-202", "calvisitor-10-105-160-95"],
    "Component": ["AddressBookSourceSync", "com.apple.ncplugin.WorldClock", "secd"],
    "PID": [31198, 91, 35382],
    "Address": ["com.apple.xpc.launchd.domain.pid.WebContent.37146", "", "com.apple.xpc.launchd.domain.pid.WebContent.39146"],
    "Content": ["scheduler_evaluate_activity told me to run this job; however, but the start time isn't for 26656 seconds.  Ignoring.", "CCDataTap::profileRemoved, Owner: com.apple.driver.AirPort.Brcm4360.0, Name: StateSnapshots", "Cocoa scripting error for '0x029f003a': four character codes must be four characters long."],
    "EventId": ["E100", "E258", "E144"],
    "EventTemplate": ["INIT -- Host controller is published", "hibernate_rebuild_pmap_structs done: last_valid_compact_indx <*", "Invalidating watch set."]
})]

# Get the number of rows in the data
num_rows = len(dfs[0])

# Update result variable
result["type"] = "number"
result["value"] = num_rows

print(result)
            ```
            
2024-09-24 22:29:50 [INFO] Executing Step 4: CachePopulation
2024-09-24 22:29:50 [INFO] Executing Step 5: CodeCleaning
2024-09-24 22:29:50 [INFO] 
Code running:
```
result = {}
num_rows = len(dfs[0])
result['type'] = 'number'
result['value'] = num_rows
print(result)
        ```
2024-09-24 22:29:50 [INFO] Executing Step 6: CodeExecution
2024-09-24 22:29:50 [INFO] Executing Step 7: ResultValidation
2024-09-24 22:29:50 [INFO] Answer: {'type': 'number', 'value': 2000}
2024-09-24 22:29:50 [INFO] Executing Step 8: ResultParsing
2024-09-24 22:31:54 [INFO] Question: What is the number of rows per minute in the data?
2024-09-24 22:31:55 [INFO] Running PandasAI with langchain_ollama-llm LLM...
2024-09-24 22:31:55 [INFO] Prompt ID: 44f61f01-bbbb-436a-8821-3f0b3011fe61
2024-09-24 22:31:55 [INFO] Executing Pipeline: GenerateChatPipeline
2024-09-24 22:31:55 [INFO] Executing Step 0: ValidatePipelineInput
2024-09-24 22:31:55 [INFO] Executing Step 1: CacheLookup
2024-09-24 22:31:55 [INFO] Executing Step 2: PromptGeneration
2024-09-24 22:31:55 [INFO] Using prompt: <dataframe>
dfs[0]:2000x11
LineId,Month,Date,Time,User,Component,PID,Address,Content,EventId,EventTemplate
1891,Jul,5,04:17:33,authorMacBook-Pro,BezelServices 255.10,33405,,CCFile::captureLog,E242,Sandbox: <*>(<*>) deny(<*>) file-read-data /private/etc/hosts
1896,Jul,1,18:02:49,calvisitor-10-105-160-179,locationd,38866,[36491],"com.apple.Safari.SafeBrowsing.Update: scheduler_evaluate_activity told me to run this job; however, but the start time isn't for 1728 seconds.  Ignoring.",E244,(ImportBailout.Error:<*>) Asked to exit for Diskarb
267,Jul,3,12:15:59,calvisitor-10-105-162-108,QQ,35877,[32626],"doSaveChannels@286: Will write to: /Library/Logs/CrashReporter/CoreCapture/IOReporters/[2017-07-03_16,27,09.307937] - AuthFail:sts:5_rsn:0.xml",E108,<*>:<*>:<*>.<*> : BTLE scanner Powered On
</dataframe>




Update this initial code:
```python
# TODO: import the required dependencies
import pandas as pd

# Write code here

# Declare result var: 
type (possible values "string", "number", "dataframe", "plot"). Examples: { "type": "string", "value": f"The highest salary is {highest_salary}." } or { "type": "number", "value": 125 } or { "type": "dataframe", "value": pd.DataFrame({...}) } or { "type": "plot", "value": "temp_chart.png" }

```



### QUERY
 What is the number of rows per minute in the data?

Variable `dfs: list[pd.DataFrame]` is already declared.

At the end, declare "result" variable as a dictionary of type and value.

If you are asked to plot a chart, use "matplotlib" for charts, save as png.


Generate python code and return full updated code:
2024-09-24 22:31:55 [INFO] Executing Step 3: CodeGenerator
2024-09-24 22:32:09 [INFO] Prompt used:
            
<dataframe>
dfs[0]:2000x11
LineId,Month,Date,Time,User,Component,PID,Address,Content,EventId,EventTemplate
1891,Jul,5,04:17:33,authorMacBook-Pro,BezelServices 255.10,33405,,CCFile::captureLog,E242,Sandbox: <*>(<*>) deny(<*>) file-read-data /private/etc/hosts
1896,Jul,1,18:02:49,calvisitor-10-105-160-179,locationd,38866,[36491],"com.apple.Safari.SafeBrowsing.Update: scheduler_evaluate_activity told me to run this job; however, but the start time isn't for 1728 seconds.  Ignoring.",E244,(ImportBailout.Error:<*>) Asked to exit for Diskarb
267,Jul,3,12:15:59,calvisitor-10-105-162-108,QQ,35877,[32626],"doSaveChannels@286: Will write to: /Library/Logs/CrashReporter/CoreCapture/IOReporters/[2017-07-03_16,27,09.307937] - AuthFail:sts:5_rsn:0.xml",E108,<*>:<*>:<*>.<*> : BTLE scanner Powered On
</dataframe>




Update this initial code:
```python
# TODO: import the required dependencies
import pandas as pd

# Write code here

# Declare result var: 
type (possible values "string", "number", "dataframe", "plot"). Examples: { "type": "string", "value": f"The highest salary is {highest_salary}." } or { "type": "number", "value": 125 } or { "type": "dataframe", "value": pd.DataFrame({...}) } or { "type": "plot", "value": "temp_chart.png" }

```



### QUERY
 What is the number of rows per minute in the data?

Variable `dfs: list[pd.DataFrame]` is already declared.

At the end, declare "result" variable as a dictionary of type and value.

If you are asked to plot a chart, use "matplotlib" for charts, save as png.


Generate python code and return full updated code:
            
2024-09-24 22:32:09 [INFO] Code generated:
            ```
            # TODO: import the required dependencies
import pandas as pd
import matplotlib.pyplot as plt

# Declare dfs variable:
dfs = [pd.DataFrame({
    "LineId": [1891, 1896, 267],
    "Month": ["Jul", "Jul", "Jul"],
    "Date": ["5", "1", "3"],
    "Time": ["04:17:33", "18:02:49", "12:15:59"],
    "User": ["authorMacBook-Pro", "calvisitor-10-105-160-179", "calvisitor-10-105-162-108"],
    "Component": ["BezelServices 255.10", "locationd", "QQ"],
    "PID": [33405, 38866, 35877],
    "Address": ["", "[36491]", "[32626]"],
    "Content": ["CCFile::captureLog", "com.apple.Safari.SafeBrowsing.Update: scheduler_evaluate_activity told me to run this job; however, but the start time isn't for 1728 seconds.  Ignoring.", "doSaveChannels@286: Will write to: /Library/Logs/CrashReporter/CoreCapture/IOReporters/[2017-07-03_16,27,09.307937] - AuthFail:sts:5_rsn:0.xml"],
    "EventId": ["E242", "E244", "E108"],
    "EventTemplate": ["Sandbox: <*>(<*>) deny(<*>) file-read-data /private/etc/hosts", "(ImportBailout.Error:<*>) Asked to exit for Diskarb", "<*>:<*>:<*>.<*> : BTLE scanner Powered On"]
})]

# Write code here
def count_rows_per_minute(dfs):
    # Convert 'Time' column to datetime and extract minute
    dfs[0]['Minute'] = pd.to_datetime(dfs[0]['Time']).dt.minute
    
    # Group by 'Minute' and count rows
    result = dfs[0].groupby('Minute')['LineId'].count()
    
    return result

result = count_rows_per_minute(dfs)

# Declare result var:
result_dict = {
    "type": "dataframe",
    "value": result
}

print(result_dict)
            ```
            
2024-09-24 22:32:09 [INFO] Executing Step 4: CachePopulation
2024-09-24 22:32:09 [INFO] Executing Step 5: CodeCleaning
2024-09-24 22:32:09 [INFO] 
Code running:
```
def count_rows_per_minute(dfs):
    dfs[0]['Minute'] = pd.to_datetime(dfs[0]['Time']).dt.minute
    result = dfs[0].groupby('Minute')['LineId'].count()
    return result


result = count_rows_per_minute(dfs)
result_dict = {'type': 'dataframe', 'value': result}
print(result_dict)
        ```
2024-09-24 22:32:09 [INFO] Executing Step 6: CodeExecution
2024-09-24 22:32:09 [ERROR] Failed with error: Traceback (most recent call last):
  File "C:\Users\regan\Documents\NUS\NUS Modules\Year 4 Semester 1\BT4103\.venv\lib\site-packages\pandasai\pipelines\chat\code_execution.py", line 96, in execute
    if not OutputValidator.validate_result(result):
  File "C:\Users\regan\Documents\NUS\NUS Modules\Year 4 Semester 1\BT4103\.venv\lib\site-packages\pandasai\helpers\output_validator.py", line 73, in validate_result
    raise InvalidOutputValueMismatch(
pandasai.exceptions.InvalidOutputValueMismatch: Result must be in the format of dictionary of type and value

2024-09-24 22:32:09 [WARNING] Failed to execute code retrying with a correction framework [retry number: 1]
2024-09-24 22:32:09 [INFO] Executing Pipeline: ErrorCorrectionPipeline
2024-09-24 22:32:09 [INFO] Executing Step 0: ErrorPromptGeneration
2024-09-24 22:32:09 [INFO] Using prompt: <dataframe>
dfs[0]:2000x11
LineId,Month,Date,Time,User,Component,PID,Address,Content,EventId,EventTemplate
1891,Jul,5,04:17:33,authorMacBook-Pro,BezelServices 255.10,33405,,CCFile::captureLog,E242,Sandbox: <*>(<*>) deny(<*>) file-read-data /private/etc/hosts
1896,Jul,1,18:02:49,calvisitor-10-105-160-179,locationd,38866,[36491],"com.apple.Safari.SafeBrowsing.Update: scheduler_evaluate_activity told me to run this job; however, but the start time isn't for 1728 seconds.  Ignoring.",E244,(ImportBailout.Error:<*>) Asked to exit for Diskarb
267,Jul,3,12:15:59,calvisitor-10-105-162-108,QQ,35877,[32626],"doSaveChannels@286: Will write to: /Library/Logs/CrashReporter/CoreCapture/IOReporters/[2017-07-03_16,27,09.307937] - AuthFail:sts:5_rsn:0.xml",E108,<*>:<*>:<*>.<*> : BTLE scanner Powered On
</dataframe>


The user asked the following question:
### QUERY
 What is the number of rows per minute in the data?

You generated this python code:
def count_rows_per_minute(dfs):
    dfs[0]['Minute'] = pd.to_datetime(dfs[0]['Time']).dt.minute
    result = dfs[0].groupby('Minute')['LineId'].count()
    return result


result = count_rows_per_minute(dfs)
result_dict = {'type': 'dataframe', 'value': result}
print(result_dict)

It fails with the following error:
Traceback (most recent call last):
  File "C:\Users\regan\Documents\NUS\NUS Modules\Year 4 Semester 1\BT4103\.venv\lib\site-packages\pandasai\pipelines\chat\code_execution.py", line 96, in execute
    if not OutputValidator.validate_result(result):
  File "C:\Users\regan\Documents\NUS\NUS Modules\Year 4 Semester 1\BT4103\.venv\lib\site-packages\pandasai\helpers\output_validator.py", line 73, in validate_result
    raise InvalidOutputValueMismatch(
pandasai.exceptions.InvalidOutputValueMismatch: Result must be in the format of dictionary of type and value


Fix the python code above and return the new python code:
2024-09-24 22:32:09 [INFO] Executing Step 1: CodeGenerator
2024-09-24 22:32:20 [INFO] Prompt used:
            
<dataframe>
dfs[0]:2000x11
LineId,Month,Date,Time,User,Component,PID,Address,Content,EventId,EventTemplate
1891,Jul,5,04:17:33,authorMacBook-Pro,BezelServices 255.10,33405,,CCFile::captureLog,E242,Sandbox: <*>(<*>) deny(<*>) file-read-data /private/etc/hosts
1896,Jul,1,18:02:49,calvisitor-10-105-160-179,locationd,38866,[36491],"com.apple.Safari.SafeBrowsing.Update: scheduler_evaluate_activity told me to run this job; however, but the start time isn't for 1728 seconds.  Ignoring.",E244,(ImportBailout.Error:<*>) Asked to exit for Diskarb
267,Jul,3,12:15:59,calvisitor-10-105-162-108,QQ,35877,[32626],"doSaveChannels@286: Will write to: /Library/Logs/CrashReporter/CoreCapture/IOReporters/[2017-07-03_16,27,09.307937] - AuthFail:sts:5_rsn:0.xml",E108,<*>:<*>:<*>.<*> : BTLE scanner Powered On
</dataframe>


The user asked the following question:
### QUERY
 What is the number of rows per minute in the data?

You generated this python code:
def count_rows_per_minute(dfs):
    dfs[0]['Minute'] = pd.to_datetime(dfs[0]['Time']).dt.minute
    result = dfs[0].groupby('Minute')['LineId'].count()
    return result


result = count_rows_per_minute(dfs)
result_dict = {'type': 'dataframe', 'value': result}
print(result_dict)

It fails with the following error:
Traceback (most recent call last):
  File "C:\Users\regan\Documents\NUS\NUS Modules\Year 4 Semester 1\BT4103\.venv\lib\site-packages\pandasai\pipelines\chat\code_execution.py", line 96, in execute
    if not OutputValidator.validate_result(result):
  File "C:\Users\regan\Documents\NUS\NUS Modules\Year 4 Semester 1\BT4103\.venv\lib\site-packages\pandasai\helpers\output_validator.py", line 73, in validate_result
    raise InvalidOutputValueMismatch(
pandasai.exceptions.InvalidOutputValueMismatch: Result must be in the format of dictionary of type and value


Fix the python code above and return the new python code:
            
2024-09-24 22:32:20 [INFO] Code generated:
            ```
            import pandas as pd

def count_rows_per_minute(dfs):
    dfs[0]['Minute'] = pd.to_datetime(dfs[0]['Time']).dt.minute
    result = dfs[0].groupby('Minute')['LineId'].count()
    return result

result = count_rows_per_minute([pd.DataFrame({
    'LineId': [1891, 1896, 267],
    'Month': ['Jul', 'Jul', 'Jul'],
    'Date': ['5', '1', '3'],
    'Time': ['04:17:33', '18:02:49', '12:15:59'],
    'User': ['authorMacBook-Pro', 'calvisitor-10-105-160-179', 'calvisitor-10-105-162-108'],
    'Component': ['BezelServices 255.10', 'locationd', 'QQ'],
    'PID': [33405, 38866, 35877],
    'Address': ['', '[36491]', '[32626]'],
    'Content': ['', '"com.apple.Safari.SafeBrowsing.Update: scheduler_evaluate_activity told me to run this job; however, but the start time isn\'t for 1728 seconds.  Ignoring."', '"doSaveChannels@286: Will write to: /Library/Logs/CrashReporter/CoreCapture/IOReporters/[2017-07-03_16,27,09.307937] - AuthFail:sts:5_rsn:0.xml"'],
    'EventId': ['E242', 'E244', 'E108'],
    'EventTemplate': ['', '(ImportBailout.Error:<*>)', '<*>:<*>:<*>.<*> : BTLE scanner Powered On']
})])

print(result.to_dict())
            ```
            
2024-09-24 22:32:20 [INFO] Executing Step 2: CodeCleaning
2024-09-24 22:32:20 [INFO] 
Code running:
```
def count_rows_per_minute(dfs):
    dfs[0]['Minute'] = pd.to_datetime(dfs[0]['Time']).dt.minute
    result = dfs[0].groupby('Minute')['LineId'].count()
    return result


result = count_rows_per_minute([pd.DataFrame({'LineId': [1891, 1896, 267], 'Month': ['Jul', 'Jul', 'Jul'], 'Date': ['5', '1', '3'], 'Time': ['04:17:33', '18:02:49', '12:15:59'], 'User': ['authorMacBook-Pro', 'calvisitor-10-105-160-179', 'calvisitor-10-105-162-108'], 'Component': ['BezelServices 255.10', 'locationd', 'QQ'], 'PID': [33405, 38866, 35877], 'Address': ['', '[36491]', '[32626]'], 'Content': ['', '"com.apple.Safari.SafeBrowsing.Update: scheduler_evaluate_activity told me to run this job; however, but the start time isn\'t for 1728 seconds.  Ignoring."', '"doSaveChannels@286: Will write to: /Library/Logs/CrashReporter/CoreCapture/IOReporters/[2017-07-03_16,27,09.307937] - AuthFail:sts:5_rsn:0.xml"'], 'EventId': ['E242', 'E244', 'E108'], 'EventTemplate': ['', '(ImportBailout.Error:<*>)', '<*>:<*>:<*>.<*> : BTLE scanner Powered On']})])
print(result.to_dict())
        ```
2024-09-24 22:32:20 [ERROR] Failed with error: Traceback (most recent call last):
  File "C:\Users\regan\Documents\NUS\NUS Modules\Year 4 Semester 1\BT4103\.venv\lib\site-packages\pandasai\pipelines\chat\code_execution.py", line 96, in execute
    if not OutputValidator.validate_result(result):
  File "C:\Users\regan\Documents\NUS\NUS Modules\Year 4 Semester 1\BT4103\.venv\lib\site-packages\pandasai\helpers\output_validator.py", line 73, in validate_result
    raise InvalidOutputValueMismatch(
pandasai.exceptions.InvalidOutputValueMismatch: Result must be in the format of dictionary of type and value

2024-09-24 22:32:20 [WARNING] Failed to execute code retrying with a correction framework [retry number: 2]
2024-09-24 22:32:20 [INFO] Executing Pipeline: ErrorCorrectionPipeline
2024-09-24 22:32:20 [INFO] Executing Step 0: ErrorPromptGeneration
2024-09-24 22:32:20 [INFO] Using prompt: <dataframe>
dfs[0]:2000x11
LineId,Month,Date,Time,User,Component,PID,Address,Content,EventId,EventTemplate
1891,Jul,5,04:17:33,authorMacBook-Pro,BezelServices 255.10,33405,,CCFile::captureLog,E242,Sandbox: <*>(<*>) deny(<*>) file-read-data /private/etc/hosts
1896,Jul,1,18:02:49,calvisitor-10-105-160-179,locationd,38866,[36491],"com.apple.Safari.SafeBrowsing.Update: scheduler_evaluate_activity told me to run this job; however, but the start time isn't for 1728 seconds.  Ignoring.",E244,(ImportBailout.Error:<*>) Asked to exit for Diskarb
267,Jul,3,12:15:59,calvisitor-10-105-162-108,QQ,35877,[32626],"doSaveChannels@286: Will write to: /Library/Logs/CrashReporter/CoreCapture/IOReporters/[2017-07-03_16,27,09.307937] - AuthFail:sts:5_rsn:0.xml",E108,<*>:<*>:<*>.<*> : BTLE scanner Powered On
</dataframe>


The user asked the following question:
### QUERY
 What is the number of rows per minute in the data?

You generated this python code:
def count_rows_per_minute(dfs):
    dfs[0]['Minute'] = pd.to_datetime(dfs[0]['Time']).dt.minute
    result = dfs[0].groupby('Minute')['LineId'].count()
    return result


result = count_rows_per_minute([pd.DataFrame({'LineId': [1891, 1896, 267], 'Month': ['Jul', 'Jul', 'Jul'], 'Date': ['5', '1', '3'], 'Time': ['04:17:33', '18:02:49', '12:15:59'], 'User': ['authorMacBook-Pro', 'calvisitor-10-105-160-179', 'calvisitor-10-105-162-108'], 'Component': ['BezelServices 255.10', 'locationd', 'QQ'], 'PID': [33405, 38866, 35877], 'Address': ['', '[36491]', '[32626]'], 'Content': ['', '"com.apple.Safari.SafeBrowsing.Update: scheduler_evaluate_activity told me to run this job; however, but the start time isn\'t for 1728 seconds.  Ignoring."', '"doSaveChannels@286: Will write to: /Library/Logs/CrashReporter/CoreCapture/IOReporters/[2017-07-03_16,27,09.307937] - AuthFail:sts:5_rsn:0.xml"'], 'EventId': ['E242', 'E244', 'E108'], 'EventTemplate': ['', '(ImportBailout.Error:<*>)', '<*>:<*>:<*>.<*> : BTLE scanner Powered On']})])
print(result.to_dict())

It fails with the following error:
Traceback (most recent call last):
  File "C:\Users\regan\Documents\NUS\NUS Modules\Year 4 Semester 1\BT4103\.venv\lib\site-packages\pandasai\pipelines\chat\code_execution.py", line 96, in execute
    if not OutputValidator.validate_result(result):
  File "C:\Users\regan\Documents\NUS\NUS Modules\Year 4 Semester 1\BT4103\.venv\lib\site-packages\pandasai\helpers\output_validator.py", line 73, in validate_result
    raise InvalidOutputValueMismatch(
pandasai.exceptions.InvalidOutputValueMismatch: Result must be in the format of dictionary of type and value


Fix the python code above and return the new python code:
2024-09-24 22:32:20 [INFO] Executing Step 1: CodeGenerator
2024-09-24 22:32:32 [INFO] Prompt used:
            
<dataframe>
dfs[0]:2000x11
LineId,Month,Date,Time,User,Component,PID,Address,Content,EventId,EventTemplate
1891,Jul,5,04:17:33,authorMacBook-Pro,BezelServices 255.10,33405,,CCFile::captureLog,E242,Sandbox: <*>(<*>) deny(<*>) file-read-data /private/etc/hosts
1896,Jul,1,18:02:49,calvisitor-10-105-160-179,locationd,38866,[36491],"com.apple.Safari.SafeBrowsing.Update: scheduler_evaluate_activity told me to run this job; however, but the start time isn't for 1728 seconds.  Ignoring.",E244,(ImportBailout.Error:<*>) Asked to exit for Diskarb
267,Jul,3,12:15:59,calvisitor-10-105-162-108,QQ,35877,[32626],"doSaveChannels@286: Will write to: /Library/Logs/CrashReporter/CoreCapture/IOReporters/[2017-07-03_16,27,09.307937] - AuthFail:sts:5_rsn:0.xml",E108,<*>:<*>:<*>.<*> : BTLE scanner Powered On
</dataframe>


The user asked the following question:
### QUERY
 What is the number of rows per minute in the data?

You generated this python code:
def count_rows_per_minute(dfs):
    dfs[0]['Minute'] = pd.to_datetime(dfs[0]['Time']).dt.minute
    result = dfs[0].groupby('Minute')['LineId'].count()
    return result


result = count_rows_per_minute([pd.DataFrame({'LineId': [1891, 1896, 267], 'Month': ['Jul', 'Jul', 'Jul'], 'Date': ['5', '1', '3'], 'Time': ['04:17:33', '18:02:49', '12:15:59'], 'User': ['authorMacBook-Pro', 'calvisitor-10-105-160-179', 'calvisitor-10-105-162-108'], 'Component': ['BezelServices 255.10', 'locationd', 'QQ'], 'PID': [33405, 38866, 35877], 'Address': ['', '[36491]', '[32626]'], 'Content': ['', '"com.apple.Safari.SafeBrowsing.Update: scheduler_evaluate_activity told me to run this job; however, but the start time isn\'t for 1728 seconds.  Ignoring."', '"doSaveChannels@286: Will write to: /Library/Logs/CrashReporter/CoreCapture/IOReporters/[2017-07-03_16,27,09.307937] - AuthFail:sts:5_rsn:0.xml"'], 'EventId': ['E242', 'E244', 'E108'], 'EventTemplate': ['', '(ImportBailout.Error:<*>)', '<*>:<*>:<*>.<*> : BTLE scanner Powered On']})])
print(result.to_dict())

It fails with the following error:
Traceback (most recent call last):
  File "C:\Users\regan\Documents\NUS\NUS Modules\Year 4 Semester 1\BT4103\.venv\lib\site-packages\pandasai\pipelines\chat\code_execution.py", line 96, in execute
    if not OutputValidator.validate_result(result):
  File "C:\Users\regan\Documents\NUS\NUS Modules\Year 4 Semester 1\BT4103\.venv\lib\site-packages\pandasai\helpers\output_validator.py", line 73, in validate_result
    raise InvalidOutputValueMismatch(
pandasai.exceptions.InvalidOutputValueMismatch: Result must be in the format of dictionary of type and value


Fix the python code above and return the new python code:
            
2024-09-24 22:32:32 [INFO] Code generated:
            ```
            import pandas as pd

def count_rows_per_minute(dfs):
    dfs[0]['Minute'] = pd.to_datetime(dfs[0]['Time']).dt.minute
    result = dfs[0].groupby('Minute')['LineId'].count()
    return result.to_dict()

result = count_rows_per_minute([pd.DataFrame({
    'LineId': [1891, 1896, 267],
    'Month': ['Jul', 'Jul', 'Jul'],
    'Date': ['5', '1', '3'],
    'Time': ['04:17:33', '18:02:49', '12:15:59'],
    'User': ['authorMacBook-Pro', 'calvisitor-10-105-160-179', 'calvisitor-10-105-162-108'],
    'Component': ['BezelServices 255.10', 'locationd', 'QQ'],
    'PID': [33405, 38866, 35877],
    'Address': ['', '[36491]', '[32626]'],
    'Content': ['', '"com.apple.Safari.SafeBrowsing.Update: scheduler_evaluate_activity told me to run this job; however, but the start time isn\'t for 1728 seconds.  Ignoring."', '"doSaveChannels@286: Will write to: /Library/Logs/CrashReporter/CoreCapture/IOReporters/[2017-07-03_16,27,09.307937] - AuthFail:sts:5_rsn:0.xml"'],
    'EventId': ['E242', 'E244', 'E108'],
    'EventTemplate': ['', '(ImportBailout.Error:<*>)', '<*>:<*>:<*>.<*> : BTLE scanner Powered On']
})])
print(result)
            ```
            
2024-09-24 22:32:32 [INFO] Executing Step 2: CodeCleaning
2024-09-24 22:32:32 [INFO] 
Code running:
```
def count_rows_per_minute(dfs):
    dfs[0]['Minute'] = pd.to_datetime(dfs[0]['Time']).dt.minute
    result = dfs[0].groupby('Minute')['LineId'].count()
    return result.to_dict()


result = count_rows_per_minute([pd.DataFrame({'LineId': [1891, 1896, 267], 'Month': ['Jul', 'Jul', 'Jul'], 'Date': ['5', '1', '3'], 'Time': ['04:17:33', '18:02:49', '12:15:59'], 'User': ['authorMacBook-Pro', 'calvisitor-10-105-160-179', 'calvisitor-10-105-162-108'], 'Component': ['BezelServices 255.10', 'locationd', 'QQ'], 'PID': [33405, 38866, 35877], 'Address': ['', '[36491]', '[32626]'], 'Content': ['', '"com.apple.Safari.SafeBrowsing.Update: scheduler_evaluate_activity told me to run this job; however, but the start time isn\'t for 1728 seconds.  Ignoring."', '"doSaveChannels@286: Will write to: /Library/Logs/CrashReporter/CoreCapture/IOReporters/[2017-07-03_16,27,09.307937] - AuthFail:sts:5_rsn:0.xml"'], 'EventId': ['E242', 'E244', 'E108'], 'EventTemplate': ['', '(ImportBailout.Error:<*>)', '<*>:<*>:<*>.<*> : BTLE scanner Powered On']})])
print(result)
        ```
2024-09-24 22:32:32 [ERROR] Failed with error: Traceback (most recent call last):
  File "C:\Users\regan\Documents\NUS\NUS Modules\Year 4 Semester 1\BT4103\.venv\lib\site-packages\pandasai\pipelines\chat\code_execution.py", line 96, in execute
    if not OutputValidator.validate_result(result):
  File "C:\Users\regan\Documents\NUS\NUS Modules\Year 4 Semester 1\BT4103\.venv\lib\site-packages\pandasai\helpers\output_validator.py", line 73, in validate_result
    raise InvalidOutputValueMismatch(
pandasai.exceptions.InvalidOutputValueMismatch: Result must be in the format of dictionary of type and value

2024-09-24 22:32:32 [WARNING] Failed to execute code retrying with a correction framework [retry number: 3]
2024-09-24 22:32:32 [INFO] Executing Pipeline: ErrorCorrectionPipeline
2024-09-24 22:32:32 [INFO] Executing Step 0: ErrorPromptGeneration
2024-09-24 22:32:32 [INFO] Using prompt: <dataframe>
dfs[0]:2000x11
LineId,Month,Date,Time,User,Component,PID,Address,Content,EventId,EventTemplate
1891,Jul,5,04:17:33,authorMacBook-Pro,BezelServices 255.10,33405,,CCFile::captureLog,E242,Sandbox: <*>(<*>) deny(<*>) file-read-data /private/etc/hosts
1896,Jul,1,18:02:49,calvisitor-10-105-160-179,locationd,38866,[36491],"com.apple.Safari.SafeBrowsing.Update: scheduler_evaluate_activity told me to run this job; however, but the start time isn't for 1728 seconds.  Ignoring.",E244,(ImportBailout.Error:<*>) Asked to exit for Diskarb
267,Jul,3,12:15:59,calvisitor-10-105-162-108,QQ,35877,[32626],"doSaveChannels@286: Will write to: /Library/Logs/CrashReporter/CoreCapture/IOReporters/[2017-07-03_16,27,09.307937] - AuthFail:sts:5_rsn:0.xml",E108,<*>:<*>:<*>.<*> : BTLE scanner Powered On
</dataframe>


The user asked the following question:
### QUERY
 What is the number of rows per minute in the data?

You generated this python code:
def count_rows_per_minute(dfs):
    dfs[0]['Minute'] = pd.to_datetime(dfs[0]['Time']).dt.minute
    result = dfs[0].groupby('Minute')['LineId'].count()
    return result.to_dict()


result = count_rows_per_minute([pd.DataFrame({'LineId': [1891, 1896, 267], 'Month': ['Jul', 'Jul', 'Jul'], 'Date': ['5', '1', '3'], 'Time': ['04:17:33', '18:02:49', '12:15:59'], 'User': ['authorMacBook-Pro', 'calvisitor-10-105-160-179', 'calvisitor-10-105-162-108'], 'Component': ['BezelServices 255.10', 'locationd', 'QQ'], 'PID': [33405, 38866, 35877], 'Address': ['', '[36491]', '[32626]'], 'Content': ['', '"com.apple.Safari.SafeBrowsing.Update: scheduler_evaluate_activity told me to run this job; however, but the start time isn\'t for 1728 seconds.  Ignoring."', '"doSaveChannels@286: Will write to: /Library/Logs/CrashReporter/CoreCapture/IOReporters/[2017-07-03_16,27,09.307937] - AuthFail:sts:5_rsn:0.xml"'], 'EventId': ['E242', 'E244', 'E108'], 'EventTemplate': ['', '(ImportBailout.Error:<*>)', '<*>:<*>:<*>.<*> : BTLE scanner Powered On']})])
print(result)

It fails with the following error:
Traceback (most recent call last):
  File "C:\Users\regan\Documents\NUS\NUS Modules\Year 4 Semester 1\BT4103\.venv\lib\site-packages\pandasai\pipelines\chat\code_execution.py", line 96, in execute
    if not OutputValidator.validate_result(result):
  File "C:\Users\regan\Documents\NUS\NUS Modules\Year 4 Semester 1\BT4103\.venv\lib\site-packages\pandasai\helpers\output_validator.py", line 73, in validate_result
    raise InvalidOutputValueMismatch(
pandasai.exceptions.InvalidOutputValueMismatch: Result must be in the format of dictionary of type and value


Fix the python code above and return the new python code:
2024-09-24 22:32:32 [INFO] Executing Step 1: CodeGenerator
2024-09-24 22:32:53 [INFO] Prompt used:
            
<dataframe>
dfs[0]:2000x11
LineId,Month,Date,Time,User,Component,PID,Address,Content,EventId,EventTemplate
1891,Jul,5,04:17:33,authorMacBook-Pro,BezelServices 255.10,33405,,CCFile::captureLog,E242,Sandbox: <*>(<*>) deny(<*>) file-read-data /private/etc/hosts
1896,Jul,1,18:02:49,calvisitor-10-105-160-179,locationd,38866,[36491],"com.apple.Safari.SafeBrowsing.Update: scheduler_evaluate_activity told me to run this job; however, but the start time isn't for 1728 seconds.  Ignoring.",E244,(ImportBailout.Error:<*>) Asked to exit for Diskarb
267,Jul,3,12:15:59,calvisitor-10-105-162-108,QQ,35877,[32626],"doSaveChannels@286: Will write to: /Library/Logs/CrashReporter/CoreCapture/IOReporters/[2017-07-03_16,27,09.307937] - AuthFail:sts:5_rsn:0.xml",E108,<*>:<*>:<*>.<*> : BTLE scanner Powered On
</dataframe>


The user asked the following question:
### QUERY
 What is the number of rows per minute in the data?

You generated this python code:
def count_rows_per_minute(dfs):
    dfs[0]['Minute'] = pd.to_datetime(dfs[0]['Time']).dt.minute
    result = dfs[0].groupby('Minute')['LineId'].count()
    return result.to_dict()


result = count_rows_per_minute([pd.DataFrame({'LineId': [1891, 1896, 267], 'Month': ['Jul', 'Jul', 'Jul'], 'Date': ['5', '1', '3'], 'Time': ['04:17:33', '18:02:49', '12:15:59'], 'User': ['authorMacBook-Pro', 'calvisitor-10-105-160-179', 'calvisitor-10-105-162-108'], 'Component': ['BezelServices 255.10', 'locationd', 'QQ'], 'PID': [33405, 38866, 35877], 'Address': ['', '[36491]', '[32626]'], 'Content': ['', '"com.apple.Safari.SafeBrowsing.Update: scheduler_evaluate_activity told me to run this job; however, but the start time isn\'t for 1728 seconds.  Ignoring."', '"doSaveChannels@286: Will write to: /Library/Logs/CrashReporter/CoreCapture/IOReporters/[2017-07-03_16,27,09.307937] - AuthFail:sts:5_rsn:0.xml"'], 'EventId': ['E242', 'E244', 'E108'], 'EventTemplate': ['', '(ImportBailout.Error:<*>)', '<*>:<*>:<*>.<*> : BTLE scanner Powered On']})])
print(result)

It fails with the following error:
Traceback (most recent call last):
  File "C:\Users\regan\Documents\NUS\NUS Modules\Year 4 Semester 1\BT4103\.venv\lib\site-packages\pandasai\pipelines\chat\code_execution.py", line 96, in execute
    if not OutputValidator.validate_result(result):
  File "C:\Users\regan\Documents\NUS\NUS Modules\Year 4 Semester 1\BT4103\.venv\lib\site-packages\pandasai\helpers\output_validator.py", line 73, in validate_result
    raise InvalidOutputValueMismatch(
pandasai.exceptions.InvalidOutputValueMismatch: Result must be in the format of dictionary of type and value


Fix the python code above and return the new python code:
            
2024-09-24 22:32:53 [INFO] Code generated:
            ```
            import pandas as pd

def count_rows_per_minute(dfs):
    dfs[0]['Minute'] = pd.to_datetime(dfs[0]['Time']).dt.minute
    result = dfs[0].groupby('Minute')['LineId'].count()
    return result.to_dict()

result = count_rows_per_minute([pd.DataFrame({
    'LineId': [1891, 1896, 267],
    'Month': ['Jul', 'Jul', 'Jul'],
    'Date': ['5', '1', '3'],
    'Time': ['04:17:33', '18:02:49', '12:15:59'],
    'User': ['authorMacBook-Pro', 'calvisitor-10-105-160-179', 'calvisitor-10-105-162-108'],
    'Component': ['BezelServices 255.10', 'locationd', 'QQ'],
    'PID': [33405, 38866, 35877],
    'Address': ['', '[36491]', '[32626]'],
    'Content': ['', '"com.apple.Safari.SafeBrowsing.Update: scheduler_evaluate_activity told me to run this job; however, but the start time isn\'t for 1728 seconds.  Ignoring."', '"doSaveChannels@286: Will write to: /Library/Logs/CrashReporter/CoreCapture/IOReporters/[2017-07-03_16,27,09.307937] - AuthFail:sts:5_rsn:0.xml"'],
    'EventId': ['E242', 'E244', 'E108'],
    'EventTemplate': ['', '(ImportBailout.Error:<*>)', '<*>:<*>:<*>.<*> : BTLE scanner Powered On']
})])
print(result)
            ```
            
2024-09-24 22:32:53 [INFO] Executing Step 2: CodeCleaning
2024-09-24 22:32:53 [INFO] 
Code running:
```
def count_rows_per_minute(dfs):
    dfs[0]['Minute'] = pd.to_datetime(dfs[0]['Time']).dt.minute
    result = dfs[0].groupby('Minute')['LineId'].count()
    return result.to_dict()


result = count_rows_per_minute([pd.DataFrame({'LineId': [1891, 1896, 267], 'Month': ['Jul', 'Jul', 'Jul'], 'Date': ['5', '1', '3'], 'Time': ['04:17:33', '18:02:49', '12:15:59'], 'User': ['authorMacBook-Pro', 'calvisitor-10-105-160-179', 'calvisitor-10-105-162-108'], 'Component': ['BezelServices 255.10', 'locationd', 'QQ'], 'PID': [33405, 38866, 35877], 'Address': ['', '[36491]', '[32626]'], 'Content': ['', '"com.apple.Safari.SafeBrowsing.Update: scheduler_evaluate_activity told me to run this job; however, but the start time isn\'t for 1728 seconds.  Ignoring."', '"doSaveChannels@286: Will write to: /Library/Logs/CrashReporter/CoreCapture/IOReporters/[2017-07-03_16,27,09.307937] - AuthFail:sts:5_rsn:0.xml"'], 'EventId': ['E242', 'E244', 'E108'], 'EventTemplate': ['', '(ImportBailout.Error:<*>)', '<*>:<*>:<*>.<*> : BTLE scanner Powered On']})])
print(result)
        ```
2024-09-24 22:32:53 [ERROR] Failed with error: Traceback (most recent call last):
  File "C:\Users\regan\Documents\NUS\NUS Modules\Year 4 Semester 1\BT4103\.venv\lib\site-packages\pandasai\pipelines\chat\code_execution.py", line 96, in execute
    if not OutputValidator.validate_result(result):
  File "C:\Users\regan\Documents\NUS\NUS Modules\Year 4 Semester 1\BT4103\.venv\lib\site-packages\pandasai\helpers\output_validator.py", line 73, in validate_result
    raise InvalidOutputValueMismatch(
pandasai.exceptions.InvalidOutputValueMismatch: Result must be in the format of dictionary of type and value

2024-09-24 22:32:53 [ERROR] Pipeline failed on step 6: Result must be in the format of dictionary of type and value
